output.csv
,ts_recv,ts_event,rtype,publisher_id,instrument_id,action,side,depth,price,size,flags,ts_in_delta,sequence,bid_px_00,bid_sz_00,bid_ct_00,ask_px_00,ask_sz_00,ask_ct_00,bid_px_01,bid_sz_01,bid_ct_01,ask_px_01,ask_sz_01,ask_ct_01,bid_px_02,bid_sz_02,bid_ct_02,ask_px_02,ask_sz_02,ask_ct_02,bid_px_03,bid_sz_03,bid_ct_03,ask_px_03,ask_sz_03,ask_ct_03,bid_px_04,bid_sz_04,bid_ct_04,ask_px_04,ask_sz_04,ask_ct_04,bid_px_05,bid_sz_05,bid_ct_05,ask_px_05,ask_sz_05,ask_ct_05,bid_px_06,bid_sz_06,bid_ct_06,ask_px_06,ask_sz_06,ask_ct_06,bid_px_07,bid_sz_07,bid_ct_07,ask_px_07,ask_sz_07,ask_ct_07,bid_px_08,bid_sz_08,bid_ct_08,ask_px_08,ask_sz_08,ask_ct_08,bid_px_09,bid_sz_09,bid_ct_09,ask_px_09,ask_sz_09,ask_ct_09,symbol,order_id
0,2025-07-29T20:12:00.887895000Z,2025-07-29T20:12:00.887895000Z,10,2,1108,S,N,0,,0,0,0,0,,0,0,,0,0,,0,0,,0,0,,0,0,,0,0,,0,0,,0,0,,0,0,,0,0,,0,0,,0,0,,0,0,,0,0,,0,0,,0,0,,0,0,,0,0,,0,0,,0,0,ARL,0
1,2025-07-29T20:12:00.888073000Z,2025-07-29T20:12:00.888073000Z,10,2,1108,S,N,0,,0,0,0,1,5.51,100,1,,0,0,,0,0,,0,0,,0,0,,0,0,,0,0,,0,0,,0,0,,0,0,,0,0,,0,0,,0,0,,0,0,,0,0,,0,0,,0,0,,0,0,,0,0,,0,0,ARL,0
2,2025-07-29T20:12:00.888120000Z,2025-07-29T20:12:00.888120000Z,10,2,1108,S,N,0,,0,0,0,2,5.51,100,1,21.33,100,1,,0,0,,0,0,,0,0,,0,0,,0,0,,0,0,,0,0,,0,0,,0,0,,0,0,,0,0,,0,0,,0,0,,0,0,,0,0,,0,0,,0,0,,0,0,ARL,0
3,2025-07-29T20:12:00.888146000Z,2025-07-29T20:12:00.888146000Z,10,2,1108,S,N,0,,0,0,0,3,5.90,100,1,21.33,100,1,5.51,100,1,,0,0,,0,0,,0,0,,0,0,,0,0,,0,0,,0,0,,0,0,,0,0,,0,0,,0,0,,0,0,,0,0,,0,0,,0,0,,0,0,,0,0,ARL,0
4,2025-07-29T20:12:00.888174000Z,2025-07-29T20:12:00.888174000Z,10,2,1108,S,N,0,,0,0,0,4,5.90,100,1,20.94,100,1,5.51,100,1,21.33,100,1,,0,0,,0,0,,0,0,,0,0,,0,0,,0,0,,0,0,,0,0,,0,0,,0,0,,0,0,,0,0,,0,0,,0,0,,0,0,,0,0,ARL,0
5,2025-07-29T20:12:00.888203000Z,2025-07-29T20:12:00.888203000Z,10,2,1108,S,N,0,,0,0,0,5,5.90,100,1,20.94,100,1,,0,0,21.33,100,1,,0,0,,0,0,,0,0,,0,0,,0,0,,0,0,,0,0,,0,0,,0,0,,0,0,,0,0,,0,0,,0,0,,0,0,,0,0,,0,0,ARL,0
6,2025-07-29T20:12:00.888228000Z,2025-07-29T20:12:00.888228000Z,10,2,1108,S,N,0,,0,0,0,6,5.90,100,1,20.94,100,1,5.37,100,1,21.33,100,1,,0,0,,0,0,,0,0,,0,0,,0,0,,0,0,,0,0,,0,0,,0,0,,0,0,,0,0,,0,0,,0,0,,0,0,,0,0,,0,0,ARL,0
7,2025-07-29T20:12:00.888276000Z,2025-07-29T20:12:00.888276000Z,10,2,1108,S,N,0,,0,0,0,7,5.37,100,1,20.94,100,1,,0,0,21.33,100,1,,0,0,,0,0,,0,0,,0,0,,0,0,,0,0,,0,0,,0,0,,0,0,,0,0,,0,0,,0,0,,0,0,,0,0,,0,0,,0,0,ARL,0
8,2025-07-29T20:12:00.888308000Z,2025-07-29T20:12:00.888308000Z,10,2,1108,S,N,0,,0,0,0,8,5.40,100,1,20.94,100,1,5.37,100,1,21.33,100,1,,0,0,,0,0,,0,0,,0,0,,0,0,,0,0,,0,0,,0,0,,0,0,,0,0,,0,0,,0,0,,0,0,,0,0,,0,0,,0,0,ARL,0
9,2025-07-29T20:12:00.888340000Z,2025-07-29T20:12:00.888340000Z,10,2,1108,S,N,0,,0,0,0,9,5.40,100,1,21.33,100,1,5.37,100,1,,0,0,,0,0,,0,0,,0,0,,0,0,,0,0,,0,0,,0,0,,0,0,,0,0,,0,0,,0,0,,0,0,,0,0,,0,0,,0,0,,0,0,ARL,0
10,2025-07-29T20:12:00.888370000Z,2025-07-29T20:12:00.888370000Z,10,2,1108,S,N,0,,0,0,0,10,5.40,100,1,21.33,100,1,5.37,100,1,21.47,100,1,,0,0,,0,0,,0,0,,0,0,,0,0,,0,0,,0,0,,0,0,,0,0,,0,0,,0,0,,0,0,,0,0,,0,0,,0,0,,0,0,ARL,0
11,2025-07-29T20:12:00.888397000Z,2025-07-29T20:12:00.888397000Z,10,2,1108,S,N,0,,0,0,0,11,5.40,100,1,21.33,100,1,,0,0,21.47,100,1,,0,0,,0,0,,0,0,,0,0,,0,0,,0,0,,0,0,,0,0,,0,0,,0,0,,0,0,,0,0,,0,0,,0,0,,0,0,,0,0,ARL,0
12,2025-07-29T20:12:00.888429000Z,2025-07-29T20:12:00.888429000Z,10,2,1108,S,N,0,,0,0,0,12,9.79,100,1,21.33,100,1,5.40,100,1,21.47,100,1,,0,0,,0,0,,0,0,,0,0,,0,0,,0,0,,0,0,,0,0,,0,0,,0,0,,0,0,,0,0,,0,0,,0,0,,0,0,,0,0,ARL,0
13,2025-07-29T20:12:00.888453000Z,2025-07-29T20:12:00.888453000Z,10,2,1108,S,N,0,,0,0,0,13,9.79,100,1,21.33,100,1,,0,0,21.47,100,1,,0,0,,0,0,,0,0,,0,0,,0,0,,0,0,,0,0,,0,0,,0,0,,0,0,,0,0,,0,0,,0,0,,0,0,,0,0,,0,0,ARL,0
14,2025-07-29T20:12:00.888488000Z,2025-07-29T20:12:00.888488000Z,10,2,1108,S,N,0,,0,0,0,14,9.84,100,1,21.33,100,1,9.79,100,1,21.47,100,1,,0,0,,0,0,,0,0,,0,0,,0,0,,0,0,,0,0,,0,0,,0,0,,0,0,,0,0,,0,0,,0,0,,0,0,,0,0,,0,0,ARL,0
15,2025-07-29T20:12:00.888513000Z,2025-07-29T20:12:00.888513000Z,10,2,1108,S,N,0,,0,0,0,15,9.84,100,1,21.47,100,1,9.79,100,1,,0,0,,0,0,,0,0,,0,0,,0,0,,0,0,,0,0,,0,0,,0,0,,0,0,,0,0,,0,0,,0,0,,0,0,,0,0,,0,0,,0,0,ARL,0
16,2025-07-29T20:12:00.888547000Z,2025-07-29T20:12:00.888547000Z,10,2,1108,S,N,0,,0,0,0,16,9.84,100,1,17.44,100,1,9.79,100,1,21.47,100,1,,0,0,,0,0,,0,0,,0,0,,0,0,,0,0,,0,0,,0,0,,0,0,,0,0,,0,0,,0,0,,0,0,,0,0,,0,0,,0,0,ARL,0
17,2025-07-29T20:12:00.888572000Z,2025-07-29T20:12:00.888572000Z,10,2,1108,S,N,0,,0,0,0,17,9.84,100,1,17.44,100,1,9.79,100,1,,0,0,,0,0,,0,0,,0,0,,0,0,,0,0,,0,0,,0,0,,0,0,,0,0,,0,0,,0,0,,0,0,,0,0,,0,0,,0,0,,0,0,ARL,0
18,2025-07-29T20:12:00.888596000Z,2025-07-29T20:12:00.888596000Z,10,2,1108,S,N,0,,0,0,0,18,9.84,100,1,17.36,100,1,9.79,100,1,17.44,100,1,,0,0,,0,0,,0,0,,0,0,,0,0,,0,0,,0,0,,0,0,,0,0,,0,0,,0,0,,0,0,,0,0,,0,0,,0,0,,0,0,ARL,0
19,2025-07-29T20:12:00.888630000Z,2025-07-29T20:12:00.888630000Z,10,2,1108,S,N,0,,0,0,0,19,9.84,100,1,17.36,100,1,9.79,100,1,,0,0,,0,0,,0,0,,0,0,,0,0,,0,0,,0,0,,0,0,,0,0,,0,0,,0,0,,0,0,,0,0,,0,0,,0,0,,0,0,,0,0,ARL,0
20,2025-07-29T20:12:00.888654000Z,2025-07-29T20:12:00.888654000Z,10,2,1108,S,N,0,,0,0,0,20,9.84,100,1,17.36,100,1,9.79,100,1,18.92,100,1,,0,0,,0,0,,0,0,,0,0,,0,0,,0,0,,0,0,,0,0,,0,0,,0,0,,0,0,,0,0,,0,0,,0,0,,0,0,,0,0,ARL,0
21,2025-07-29T20:12:00.888686000Z,2025-07-29T20:12:00.888686000Z,10,2,1108,S,N,0,,0,0,0,21,9.84,100,1,18.92,100,1,9.79,100,1,,0,0,,0,0,,0,0,,0,0,,0,0,,0,0,,0,0,,0,0,,0,0,,0,0,,0,0,,0,0,,0,0,,0,0,,0,0,,0,0,,0,0,ARL,0
22,2025-07-29T20:12:00.888712000Z,2025-07-29T20:12:00.888712000Z,10,2,1108,S,N,0,,0,0,0,22,9.84,100,1,18.84,100,1,9.79,100,1,18.92,100,1,,0,0,,0,0,,0,0,,0,0,,0,0,,0,0,,0,0,,0,0,,0,0,,0,0,,0,0,,0,0,,0,0,,0,0,,0,0,,0,0,ARL,0
23,2025-07-29T20:12:00.888737000Z,2025-07-29T20:12:00.888737000Z,10,2,1108,S,N,0,,0,0,0,23,9.84,100,1,18.84,100,1,9.79,100,1,,0,0,,0,0,,0,0,,0,0,,0,0,,0,0,,0,0,,0,0,,0,0,,0,0,,0,0,,0,0,,0,0,,0,0,,0,0,,0,0,,0,0,ARL,0
24,2025-07-29T20:12:00.888761000Z,2025-07-29T20:12:00.888761000Z,10,2,1108,S,N,0,,0,0,0,24,9.84,100,1,18.84,100,1,9.79,100,1,20.62,100,1,,0,0,,0,0,,0,0,,0,0,,0,0,,0,0,,0,0,,0,0,,0,0,,0,0,,0,0,,0,0,,0,0,,0,0,,0,0,,0,0,ARL,0
25,2025-07-29T20:12:00.888785000Z,2025-07-29T20:12:00.888785000Z,10,2,1108,S,N,0,,0,0,0,25,9.84,100,1,20.62,100,1,9.79,100,1,,0,0,,0,0,,0,0,,0,0,,0,0,,0,0,,0,0,,0,0,,0,0,,0,0,,0,0,,0,0,,0,0,,0,0,,0,0,,0,0,,0,0,ARL,0
26,2025-07-29T20:12:00.888809000Z,2025-07-29T20:12:00.888809000Z,10,2,1108,S,N,0,,0,0,0,26,9.84,100,1,20.53,100,1,9.79,100,1,20.62,100,1,,0,0,,0,0,,0,0,,0,0,,0,0,,0,0,,0,0,,0,0,,0,0,,0,0,,0,0,,0,0,,0,0,,0,0,,0,0,,0,0,ARL,0
27,2025-07-29T20:12:00.888834000Z,2025-07-29T20:12:00.888834000Z,10,2,1108,S,N,0,,0,0,0,27,9.84,100,1,20.53,100,1,9.79,100,1,,0,0,,0,0,,0,0,,0,0,,0,0,,0,0,,0,0,,0,0,,0,0,,0,0,,0,0,,0,0,,0,0,,0,0,,0,0,,0,0,,0,0,ARL,0
28,2025-07-29T20:12:00.888858000Z,2025-07-29T20:12:00.888858000Z,10,2,1108,S,N,0,,0,0,0,28,9.84,100,1,20.53,100,1,9.79,100,1,21.47,100,1,,0,0,,0,0,,0,0,,0,0,,0,0,,0,0,,0,0,,0,0,,0,0,,0,0,,0,0,,0,0,,0,0,,0,0,,0,0,,0,0,ARL,0
29,2025-07-29T20:12:00.888882000Z,2025-07-29T20:12:00.888882000Z,10,2,1108,S,N,0,,0,0,0,29,9.84,100,1,21.47,100,1,9.79,100,1,,0,0,,0,0,,0,0,,0,0,,0,0,,0,0,,0,0,,0,0,,0,0,,0,0,,0,0,,0,0,,0,0,,0,0,,0,0,,0,0,,0,0,ARL,0
30,2025-07-29T20:12:00.888915000Z,2025-07-29T20:12:00.888915000Z,10,2,1108,S,N,0,,0,0,0,30,9.84,100,1,21.47,200,2,9.79,100,1,,0,0,,0,0,,0,0,,0,0,,0,0,,0,0,,0,0,,0,0,,0,0,,0,0,,0,0,,0,0,,0,0,,0,0,,0,0,,0,0,,0,0,ARL,0
31,2025-07-29T20:12:00.888939000Z,2025-07-29T20:12:00.888939000Z,10,2,1108,S,N,0,,0,0,0,31,9.84,100,1,21.47,100,1,9.79,100,1,,0,0,,0,0,,0,0,,0,0,,0,0,,0,0,,0,0,,0,0,,0,0,,0,0,,0,0,,0,0,,0,0,,0,0,,0,0,,0,0,,0,0,ARL,0
32,2025-07-29T20:12:00.888962000Z,2025-07-29T20:12:00.888962000Z,10,2,1108,S,N,0,,0,0,0,32,9.84,100,1,17.44,100,1,9.79,100,1,21.47,100,1,,0,0,,0,0,,0,0,,0,0,,0,0,,0,0,,0,0,,0,0,,0,0,,0,0,,0,0,,0,0,,0,0,,0,0,,0,0,,0,0,ARL,0
33,2025-07-29T20:12:00.888987000Z,2025-07-29T20:12:00.888987000Z,10,2,1108,S,N,0,,0,0,0,33,9.84,100,1,17.44,100,1,9.79,100,1,,0,0,,0,0,,0,0,,0,0,,0,0,,0,0,,0,0,,0,0,,0,0,,0,0,,0,0,,0,0,,0,0,,0,0,,0,0,,0,0,,0,0,ARL,0
